Workbook

Sheet Portada
A1: Casos de Prueba
A2: [Nombre del proyecto] (tablero [CLAVE])
A4: Entregable | B4: Matriz de Responsabilidades de Documentación - rol Aseguramiento de Calidad (QA)
A5: Documentos que cubre | B5: Casos de prueba funcionales y pruebas no funcionales de las historias del tablero [CLAVE] ([Sprint]: [lista de historias]). Escenarios de estrés y carga en la hoja «Escenarios Estrés y Carga».
A6: Responsable | B6: [Nombre y apellido], [rol]
A7: Versión | B7: 0.1
A8: Fecha de elaboración | B8: [dd/mm/aaaa] · [Sprint o periodo: fecha inicio al fecha fin]
A9: Estado | B9: Borrador ( ) En revisión (X) Aprobado ( )
A10: Aprobado por | B10: Scrum Master / Product Owner de [Proyecto]
A12: Cómo se usa este libro
A14: Casos de Prueba | B14: Casos funcionales. Antes de ejecutar se escriben todas las columnas blancas. Durante la ejecución se llenan las amarillas: Resultado obtenido, Estado, Defecto, Evidencia, Ejecutado por y Fecha. Test automatizado, Entorno y Commit probado dicen qué prueba respalda el caso, contra qué se ejecutó y sobre qué versión del código.
A15: Pruebas No Funcionales | B15: Miden cómo se comporta el sistema (rapidez, aguante, límites, recuperación), no qué hace. Cada fila tiene su Tipo; ver la leyenda más abajo. Si no aplica en un ciclo, la hoja (y Escenarios Estrés y Carga) se deja visible con la nota «No aplica en este ciclo».
A16: Regresión | B16: Suite para repetir cuando se corrigen defectos. Humo: flujo principal de cada historia, va primero. Reprueba: los casos que fallaron, se repiten cuando su defecto pasa a «Corregido». Regresión: casos Críticos y Altos que ya pasan, para comprobar que la corrección no rompió nada.
A17: Resumen | B17: Se calcula solo a partir de las hojas Casos de Prueba, Pruebas No Funcionales y Regresión. No escribir en ella.
A18: Usuarios de prueba | B18: Por definir: las cuentas de prueba de [Proyecto] se anotan aquí al escribir los casos. La contraseña está en el seed de usuarios de prueba (no se copia aquí).
A19: Evidencias | B19: Al ejecutar un caso se escribe en la columna Evidencia el ID del archivo (EV-CP-xxx) registrado en Registro_de_Evidencias.xlsx (carpeta 03).
A21: Leyenda de Estado
A23: Pendiente | B23: Todavía no se ejecuta.
A24: Aprobado | B24: El resultado obtenido coincide con el esperado.
A25: Fallido | B25: No coincide. Debe existir un número de defecto (DEF-xx) en la columna Defecto.
A26: Bloqueado | B26: No se pudo ejecutar por una causa externa: HU sin desarrollar, ambiente caído o dato no disponible.
A27: No aplica | B27: La funcionalidad no está en esta versión.
A29: Tipos de prueba no funcional (hoja Pruebas No Funcionales)
A31: Carga | B31: ¿Aguanta el uso normal en hora pico? Se aplica la carga esperada y se mide si cumple la meta.
A32: Estrés | B32: ¿Hasta dónde aguanta y cómo falla? Se sube la carga por encima de lo normal, en escalones, hasta encontrar el punto de quiebre.
A33: Volumen | B33: ¿Sigue rápido con muchos datos acumulados? La carga de usuarios es baja; lo grande es la cantidad de datos.
A34: Límites | B34: ¿Respeta los topes definidos? Se prueba justo en el máximo permitido y justo por encima.
A35: Recuperación | B35: ¿Queda consistente después de una falla? Se corta el servidor o la red a mitad de una operación.
A37: Estado de las pruebas no funcionales
A39: Pendiente | B39: Todavía no se ejecuta.
A40: Cumple | B40: El resultado alcanza la meta acordada.
A41: No cumple | B41: No alcanza la meta. Se registra un defecto.
A42: Informativo | B42: Se midió sin una meta definida: el dato queda como referencia.
A43: Bloqueado | B43: No se pudo ejecutar (HU sin desarrollar o ambiente no disponible).
A45: Tipos de caso funcional (hoja Casos de Prueba)
A47: Funcional | B47: Camino feliz de la funcionalidad.
A48: Negativa | B48: Entrada inválida: el sistema debe rechazarla sin dejar datos a medias.
A49: Límite | B49: Valores en el borde de una regla (tamaños, fechas, cantidades).
A50: Seguridad | B50: Permisos por rol, en la pantalla y en la API. Va aquí y no en No Funcionales porque cada permiso es un criterio de aceptación de la HU.
A51: E2E | B51: Recorrido completo hasta el entregable (PDF, Excel).
...

Sheet Casos de Prueba
A1: ID | B1: Historia | C1: Requisito | D1: Tipo | E1: Prioridad | F1: Rol / usuario | G1: Precondición | H1: Pasos | I1: Datos de prueba | J1: Resultado esperado | K1: Resultado obtenido | L1: Estado | M1: Defecto | N1: Evidencia | O1: Ejecutado por | P1: Fecha | Q1: Test automatizado | R1: Entorno | S1: Commit probado

Sheet Regresión
A1: ID | B1: Nivel | C1: Caso | D1: Historia | E1: Requisito | F1: Prioridad | G1: Qué verifica | H1: Por qué está en la suite | I1: Cuándo se ejecuta | J1: Defecto relacionado | K1: Script (qa/automatizacion) | L1: Resultado previo [dd/mm/aaaa] | M1: Resultado regresión | N1: Fecha | O1: Ejecutado por | P1: Observación | Q1: Sprint | R1: Evidencia | S1: Fallos de entorno

Sheet Escenarios Estrés y Carga
A1: ID | B1: Tipo | C1: Historia | D1: Escenario | E1: Objetivo | F1: Carga o condición | G1: Duración | H1: Precondiciones | I1: Qué se mide | J1: Meta | K1: Referencia de la meta | L1: Herramienta | M1: Cómo se ejecuta
A14: Notas de los escenarios
A15: Documento
A16: Objetivo
A17: Alcance
A18: Tipos de prueba
A19: Cómo se fijan las metas
A20: Ambiente
A21: Datos y usuarios
A22: Herramienta
A23: Orden y precauciones
A24: Advertencia

Sheet Pruebas No Funcionales
A1: ID | B1: Tipo | C1: Historia | D1: Escenario | E1: Carga o condición aplicada | F1: Métrica observada | G1: Meta acordada | H1: Herramienta | I1: Resultado obtenido | J1: Estado | K1: Observación

Sheet Resumen
A1: Resumen de ejecución
A3: Se calcula solo. No escribir en esta hoja.
A5: Indicador | B5: Cantidad | C5: % del total
A6: Total de casos | B6: =COUNTA('Casos de Prueba'!A2:A200)
A7: Pendientes | B7: =COUNTIF('Casos de Prueba'!L2:L200,"Pendiente") | C7: =IF(B6=0,0,B7/B6)
A8: Aprobados | B8: =COUNTIF('Casos de Prueba'!L2:L200,"Aprobado") | C8: =IF(B6=0,0,B8/B6)
A9: Fallidos | B9: =COUNTIF('Casos de Prueba'!L2:L200,"Fallido") | C9: =IF(B6=0,0,B9/B6)
A10: Bloqueados | B10: =COUNTIF('Casos de Prueba'!L2:L200,"Bloqueado") | C10: =IF(B6=0,0,B10/B6)
A11: No aplica | B11: =COUNTIF('Casos de Prueba'!L2:L200,"No aplica") | C11: =IF(B6=0,0,B11/B6)
A12: Casos críticos | B12: =COUNTIF('Casos de Prueba'!E2:E200,"Crítica") | C12: =IF(B6=0,0,B12/B6)
A13: Críticos aprobados | B13: =COUNTIFS('Casos de Prueba'!E2:E200,"Crítica",'Casos de Prueba'!L2:L200,"Aprobado") | C13: =IF(B12=0,0,B13/B12)
A15: Pruebas no funcionales por tipo
A16: Indicador | B16: Cantidad | C16: % del total
A17: Total no funcionales | B17: =COUNTA('Pruebas No Funcionales'!A2:A200)
A18: Carga | B18: =COUNTIF('Pruebas No Funcionales'!B2:B200,"Carga") | C18: =IF(B17=0,0,B18/B17)
A19: Estrés | B19: =COUNTIF('Pruebas No Funcionales'!B2:B200,"Estrés") | C19: =IF(B17=0,0,B19/B17)
A20: Volumen | B20: =COUNTIF('Pruebas No Funcionales'!B2:B200,"Volumen") | C20: =IF(B17=0,0,B20/B17)
A21: Límites | B21: =COUNTIF('Pruebas No Funcionales'!B2:B200,"Límites") | C21: =IF(B17=0,0,B21/B17)
A22: Recuperación | B22: =COUNTIF('Pruebas No Funcionales'!B2:B200,"Recuperación") | C22: =IF(B17=0,0,B22/B17)
A24: Pruebas no funcionales por estado
A25: Indicador | B25: Cantidad | C25: % del total
A26: Total no funcionales | B26: =COUNTA('Pruebas No Funcionales'!A2:A200)
A27: Pendiente | B27: =COUNTIF('Pruebas No Funcionales'!J2:J200,"Pendiente") | C27: =IF(B26=0,0,B27/B26)
A28: Cumple | B28: =COUNTIF('Pruebas No Funcionales'!J2:J200,"Cumple") | C28: =IF(B26=0,0,B28/B26)
A29: No cumple | B29: =COUNTIF('Pruebas No Funcionales'!J2:J200,"No cumple") | C29: =IF(B26=0,0,B29/B26)
A30: Informativo | B30: =COUNTIF('Pruebas No Funcionales'!J2:J200,"Informativo") | C30: =IF(B26=0,0,B30/B26)
A31: Bloqueado | B31: =COUNTIF('Pruebas No Funcionales'!J2:J200,"Bloqueado") | C31: =IF(B26=0,0,B31/B26)
A33: Resultado por historia
A34: Historia | B34: Total | C34: Aprobados | D34: Fallidos | E34: Bloqueados | F34: Críticos fallidos | G34: Veredicto
A35: — | B35: =COUNTIF('Casos de Prueba'!B2:B200,LEFT($A35,FIND(" ",$A35&" ")-1)) | C35: =COUNTIFS('Casos de Prueba'!B2:B200,LEFT($A35,FIND(" ",$A35&" ")-1),'Casos de Prueba'!L2:L200,"Aprobado") | D35: =COUNTIFS('Casos de Prueba'!B2:B200,LEFT($A35,FIND(" ",$A35&" ")-1),'Casos de Prueba'!L2:L200,"Fallido") | E35: =COUNTIFS('Casos de Prueba'!B2:B200,LEFT($A35,FIND(" ",$A35&" ")-1),'Casos de Prueba'!L2:L200,"Bloqueado") | F35: =COUNTIFS('Casos de Prueba'!B2:B200,LEFT($A35,FIND(" ",$A35&" ")-1),'Casos de Prueba'!L2:L200,"Fallido",'Casos de Prueba'!E2:E200,"Crítica")+COUNTIFS('Casos de Prueba'!B2:B200,LEFT($A35,FIND(" ",$A35&" ")-1),'Casos de Prueba'!L2:L200,"Bloqueado",'Casos de Prueba'!E2:E200,"Crítica") | G35: =IF(B35=0,"Sin casos",IF(SUM(C35:E35)<B35,"Pendiente",IF(D35+E35=0,"Pasa","No pasa")))
A36: — | B36: =COUNTIF('Casos de Prueba'!B2:B200,LEFT($A36,FIND(" ",$A36&" ")-1)) | C36: =COUNTIFS('Casos de Prueba'!B2:B200,LEFT($A36,FIND(" ",$A36&" ")-1),'Casos de Prueba'!L2:L200,"Aprobado") | D36: =COUNTIFS('Casos de Prueba'!B2:B200,LEFT($A36,FIND(" ",$A36&" ")-1),'Casos de Prueba'!L2:L200,"Fallido") | E36: =COUNTIFS('Casos de Prueba'!B2:B200,LEFT($A36,FIND(" ",$A36&" ")-1),'Casos de Prueba'!L2:L200,"Bloqueado") | F36: =COUNTIFS('Casos de Prueba'!B2:B200,LEFT($A36,FIND(" ",$A36&" ")-1),'Casos de Prueba'!L2:L200,"Fallido",'Casos de Prueba'!E2:E200,"Crítica")+COUNTIFS('Casos de Prueba'!B2:B200,LEFT($A36,FIND(" ",$A36&" ")-1),'Casos de Prueba'!L2:L200,"Bloqueado",'Casos de Prueba'!E2:E200,"Crítica") | G36: =IF(B36=0,"Sin casos",IF(SUM(C36:E36)<B36,"Pendiente",IF(D36+E36=0,"Pasa","No pasa")))
A38: Por qué falla cada historia: Matriz_de_Trazabilidad_RTM.xlsx, hoja Historias, columna «Por qué no pasa».
A39: La cobertura de requisitos se calcula en Matriz_de_Trazabilidad_RTM.xlsx (carpeta 05).
A40: Los defectos se registran en Registro_de_Defectos.xlsx (carpeta 04).
A41: Criterio de cierre: 100 % de los casos críticos aprobados, ningún defecto Crítico o Alto abierto y ningún requisito sin cubrir.
A42: Suite de regresión (hoja Regresión)
A43: Indicador | B43: Cantidad | C43: Aprobados | D43: Fallidos | E43: Pendientes
A44: Total | B44: =COUNTA(Regresión!A2:A200) | C44: =COUNTIF(Regresión!M2:M200,"Aprobado") | D44: =COUNTIF(Regresión!M2:M200,"Fallido") | E44: =COUNTIF(Regresión!M2:M200,"Pendiente")
A45: Humo | B45: =COUNTIF(Regresión!B2:B200,"Humo") | C45: =COUNTIFS(Regresión!B2:B200,"Humo",Regresión!M2:M200,"Aprobado") | D45: =COUNTIFS(Regresión!B2:B200,"Humo",Regresión!M2:M200,"Fallido") | E45: =COUNTIFS(Regresión!B2:B200,"Humo",Regresión!M2:M200,"Pendiente")
A46: Reprueba | B46: =COUNTIF(Regresión!B2:B200,"Reprueba") | C46: =COUNTIFS(Regresión!B2:B200,"Reprueba",Regresión!M2:M200,"Aprobado") | D46: =COUNTIFS(Regresión!B2:B200,"Reprueba",Regresión!M2:M200,"Fallido") | E46: =COUNTIFS(Regresión!B2:B200,"Reprueba",Regresión!M2:M200,"Pendiente")
...
