Workbook

Sheet Portada
A1: Registro de Defectos
A2: Pangea (tablero PP)
A4: Entregable | B4: Matriz de Responsabilidades de Documentación - rol Aseguramiento de Calidad (QA)
A5: Documentos que cubre | B5: Defectos, observaciones y entregas pendientes de HT-06 y HU-18, con el historial de rondas.
A6: Responsable | B6: Elliot (JS en Jira), QA / Tester
A7: Versión | B7: 0.3
A8: Fecha de elaboración | B8: 30/10/2026 · Ronda 1 de HT-06 y ronda 2 de HU-18
A9: Estado | B9: Borrador (X) En revisión ( ) Aprobado ( )
A10: Aprobado por | B10: Scrum Master / Product Owner de Pangea
A12: Cómo se usa este libro
A14: Defectos | B14: Empieza vacía. Se agrega una fila solo cuando un caso falla, numerando en orden DEF-01, DEF-02… El ID se copia en la columna Defecto del caso Fallido. Fuera de esta carpeta se cita con prefijo (PP:DEF-01).
A15: Observaciones | B15: Hallazgos que no hacen fallar el caso. Cada una lleva tipo, severidad y responsable (PO, Dev o QA), para ver de un vistazo quién debe actuar. Se numeran OBS-01, OBS-02…
A16: Pendientes de entrega | B16: Subtareas del tablero que no se entregaron. No son defectos, pero bloquean el cierre de la HU. Se numeran PEN-01, PEN-02…
A17: Historial de rondas | B17: Una fila por HU en cada ronda de ejecución: fecha, commit probado, resultados y defectos. Es una foto de cada ronda: no se recalcula.
A18: Ciclo de vida | B18: Nuevo → Asignado → En corrección → Corregido → Cerrado. «Pendiente» = registrado y todavía sin asignar. «Corregido» lo marca QA cuando la corrección llega a dev (se anota el commit); «Cerrado» solo después de la reprueba de QA (columna Reprueba, hoja Regresión de Casos_de_Prueba.xlsx). Si la reprueba falla: Reabierto.
A19: Mantenimiento | B19: Cada vez que llegan cambios a dev: revisar los commits, pasar a «Corregido» lo que corrigen (con el commit en Comentarios) y anotar «sin cambios» en el resto. Después de la reprueba: «Cerrado» o «Reabierto». Al cierre de cada sprint se revisa que ningún defecto quede sin estado ni sin responsable.
A20: Resumen | B20: Se calcula solo. No escribir en ella.
A22: Severidad (impacto en el sistema)
A24: Crítica | B24: Bloquea una función crítica o de seguridad del sistema, o produce un resultado incorrecto con consecuencias graves; no hay alternativa.
A25: Alta | B25: La funcionalidad principal de la HU no cumple y no hay alternativa.
A26: Media | B26: Falla parcial con alternativa, o mensaje/validación incorrecta.
A27: Baja | B27: Cosmético: textos, alineación, ortografía.
A29: Prioridad (urgencia de corrección)
A31: Alta | B31: Se corrige en el sprint actual.
A32: Media | B32: Próximo sprint.
A33: Baja | B33: Cuando haya capacidad.

Sheet Defectos
A1: ID | B1: Título | C1: Historia | D1: Requisito | E1: Caso | F1: Severidad | G1: Prioridad | H1: Ambiente | I1: Pasos para reproducir | J1: Resultado esperado | K1: Resultado obtenido | L1: Evidencia | M1: Reportado por | N1: Fecha reporte | O1: Asignado a | P1: Estado | Q1: Fecha cierre | R1: Comentarios / resolución | S1: Reprueba (hoja Regresión)
A2: DEF-01 | B2: Base de datos de produccion con acceso publico desde internet | C2: HT-06 | D2: RQ-HT06-02 | E2: CP-006, CP-007, CP-008 | F2: Crítica | G2: Alta | H2: Producción | I2: 1. Abrir AWS CloudShell. 2. aws lightsail get-relational-databases y leer publiclyAccessible de pangea-db. 3. Intentar conexion TCP al puerto 5432 desde CloudShell. | J2: publiclyAccessible = False y conexion rechazada desde fuera de Lightsail | K2: publiclyAccessible = True; la conexion TCP al puerto 5432 queda abierta desde internet | L2: lightsail_verificacion_resumen.txt | M2: QA | N2: 28/10/2026 | O2: Jareth (autor del despliegue) | P2: Nuevo | R2: Antes de poner la BD en modo privado confirmar que el Container Service esta conectado por VPC peering; si no, la API perderia la conexion. Falta ademas documentar el modo privado. | S2: —
A3: DEF-02 | B3: Credenciales de produccion expuestas en el historial de git sin rotar | C3: HT-06 | D3: RQ-HT06-05 | E3: CP-023, CP-024 | F3: Crítica | G3: Alta | H3: Producción | I3: 1. git log --all -p -S rds.amazonaws.com -- containers.json endpoint.json. 2. Revisar el commit dba450f. | J3: Ningun secreto en el historial, o secretos rotados | K3: El commit dba450f subio containers.json con la cadena de conexion de la BD (usuario y contrasena), JWT_SECRET y FTP_CREDENTIAL_KEY en texto plano; el commit ac48238 los quito del codigo actual pero dejo la rotacion pendiente | L3: test_ht06_local.py::test_ca5_historial_git_sin_contrasena_de_bd_remota y test_ca5_secretos_jwt_y_ftp_no_en_historial (pytest_ht06_local.html) | M3: QA | N3: 28/10/2026 | O3: Jareth (autor del despliegue) | P3: Nuevo | R3: Rotar la contrasena de la BD, JWT_SECRET y FTP_CREDENTIAL_KEY en el Container Service y en la BD, y reescribir o aceptar el historial (decision del PO). Las claves rotadas no se escriben en el repositorio. | S3: —
A4: DEF-03 | B4: docker-compose: el worker y el beat no pueden conectarse a la BD local | C4: HT-06 | D4: RQ-HT06-01 | E4: CP-004 | F4: Media | G4: Media | H4: Local | I4: 1. docker compose --profile full up -d --build. 2. docker compose --profile full logs worker. | J4: worker y beat ejecutan sus tareas contra la BD del compose | K4: El servicio db crea el usuario postgres (clave postgres) y api, worker y beat se conectan como pangea:pangea_dev: 'password authentication failed for user pangea' en cada tarea | L4: docker_local_ca1.txt | M4: QA | N4: 28/10/2026 | O4: Dev (por asignar) | P4: Nuevo | R4: Alinear POSTGRES_USER y POSTGRES_PASSWORD del servicio db con la DATABASE_URL de api, worker y beat en docker-compose.yml. | S4: —
A5: DEF-04 | B5: Desactivar un dispositivo no detiene el polling FTP: el sondeo sigue revisando su conexión y registrando archivos | C5: HU-18 | D5: RQ-HU18-02 | E5: CP-039, CP-051 | F5: Alta | G5: Alta | H5: Local | I5: 1. Levantar un FTP local con H_antes.dat y un dispositivo Activo con su conexión. 2. Ejecutar sondear_conexiones_ftp: detecta H_antes.dat. 3. Desactivar el dispositivo (DELETE /dispositivos/{id}). 4. Subir H_despues.dat, vencer la frecuencia de sondeo y ejecutar de nuevo el sondeo. | J5: El sondeo no se conecta al FTP del dispositivo desactivado ni registra archivos nuevos (PP-190, CA2: se detiene la ingesta de ese equipo) | K5: El sondeo sigue conectándose, crea el registro de H_despues.dat y encola procesar_archivo_dat. Ese job fallaría después con DispositivoNoResueltoError (no hay dispositivo Activo); no se ejecutó el worker. | L5: pytest_hu18.html y pytest_hu18_ftp_real.html (EV-HU18-INF-01, EV-HU18-INF-02) | M5: QA | N5: 28/10/2026 | O5: Jareth | P5: Cerrado | Q5: 30/10/2026 | R5: sondear_conexiones_ftp (backend/app/tasks/ingesta.py) filtra solo por ConexionFTP.estd = 'Activa' y no mira Dispositivo.estd. Solución: sondear solo las conexiones que tengan un dispositivo Activo (exists sobre Dispositivo.id_cnxn con estd = 'Activo'). El código de la HU18 (commit 2db9325) no tiene un autor identificable en git. Reprueba RG-05 y RG-06; CP-040 y CP-041 deben seguir aprobados. Ronda 2 (30/10/2026): Jareth agregó en sondear_conexiones_ftp un exists() sobre Dispositivo.estd = 'Activo' (commit dccdb60) y pruebas en tests/tasks/test_sondeo_ftp.py. QA lo verificó en 27ac90a: CP-039, CP-051 y RG-05 a RG-07 aprobados; reactivar reanuda el sondeo (CP-041). | S5: RG-05, RG-06 (aprobadas en la ronda 2)

Sheet Observaciones
A1: ID | B1: Caso | C1: Historia | D1: Observación | E1: Sugerencia | F1: Reportado por | G1: Fecha | H1: Estado | I1: Tipo | J1: Severidad | K1: Responsable | L1: Fecha límite | M1: Fecha de cierre | N1: Resolución
A2: OBS-01 | B2: CP-005 | C2: HT-06 | D2: El receptor FTP/TCP pedido por la HU no existe como contenedor; la ingesta funciona por sondeo desde Celery | E2: Confirmar si el sondeo reemplaza al receptor y, si es asi, actualizar la HU | F2: QA | G2: 28/10/2026 | H2: Abierta | I2: Decisión del PO | J2: Media | K2: PO
A3: OBS-02 | B3: CP-003 | C3: HT-06 | D3: containers.example.json usa el servicio pangea-app y el servicio real se llama pangea-api | E3: Actualizar la plantilla con el nombre real | F3: QA | G3: 28/10/2026 | H3: Abierta | I3: Mejora técnica | J3: Baja | K3: Dev
A4: OBS-03 | B4: CP-003 | C4: HT-06 | D4: Redis corre dentro del mismo servicio, sin volumen: la cola y la cache se pierden en cada redeploy | E4: Evaluar un Redis administrado o persistencia | F4: QA | G4: 28/10/2026 | H4: Abierta | I4: Mejora técnica | J4: Media | K4: Dev
A5: OBS-04 | B5: CP-009 | C5: HT-06 | D5: El bucket pangea-storage-prod no tiene versionado (NeverEnabled) | E5: Activar el versionado si se guardaran respaldos | F5: QA | G5: 28/10/2026 | H5: Abierta | I5: Mejora técnica | J5: Baja | K5: Dev
A6: OBS-05 | B6: CP-013 | C6: HT-06 | D6: La persistencia tras un redeploy no se probo: produccion es compartida y el servidor de pruebas esta en curso | E6: Probar en el servidor de pruebas cuando exista | F6: QA | G6: 28/10/2026 | H6: Abierta | I6: Cobertura pendiente | J6: Media | K6: PO
A7: OBS-06 | B7: CP-004 | C7: HT-06 | D7: Docker Desktop y AWS CLI no estaban instalados en el equipo de QA | E7: Se instalaron el 28/10/2026 | F7: QA | G7: 28/10/2026 | H7: Aceptada | I7: Entorno | J7: Baja | K7: QA | M7: 28/10/2026 | N7: Se instalaron Docker Desktop y AWS CLI
A8: OBS-07 | B8: CP-003 | C8: HT-06 | D8: El Container Service tiene 4 contenedores en un servicio con escala 1: no se puede escalar cada componente por separado | E8: Decidir si se separan en servicios | F8: QA | G8: 28/10/2026 | H8: Abierta | I8: Decisión del PO | J8: Media | K8: PO
A9: OBS-08 | B9: — | C9: HT-06 | D9: Instancia Servidores-ceneris (ajena a Pangea): bases publicadas en 0.0.0.0 (puertos 5437 y 3307), 45 actualizaciones, reinicio pendiente y swap al 80 % | E9: Revisar el firewall de la instancia | F9: QA | G9: 28/10/2026 | H9: Trasladada | I9: Ajena a la HU | J9: Media | K9: PO | N9: Se informa al responsable de la instancia
A10: OBS-09 | B10: CP-034 | C10: HU-18 | D10: Con la regla comercial vigente (exigir_operacion, backend/app/services/contratos.py, commit b948aac) desactivar y reactivar un dispositivo devuelve 409 «La empresa está en modo consulta» si la empresa no tiene suscripción vigente. La HU18 no menciona esa condición: en ese caso un Técnico CENERIS no puede detener la ingesta de un equipo. | E10: El PO confirma si desactivar debe poder hacerse en modo consulta (donde la ingesta se conserva) o si la restricción es intencional y se documenta en la HU. | F10: QA | G10: 28/10/2026 | H10: Abierta | I10: Decisión del PO | J10: Media | K10: PO
A11: OBS-10 | B11: CP-052 | C11: HU-18 | D11: El botón de confirmación del modal se llama «Desactivar» (con la cuenta regresiva «Desactivar (3)»), no «CONFIRMAR» como dice el CA2. El comportamiento pedido (confirmar cambia a Inactivo y muestra el mensaje) se cumple. | E11: Que el PO acepte la etiqueta actual o pida cambiarla a CONFIRMAR. | F11: QA | G11: 28/10/2026 | H11: Abierta | I11: Decisión del PO | J11: Baja | K11: PO
A12: OBS-11 | B12: CP-030 | C12: HU-18 | D12: Tras la suscripción obligatoria (commit b948aac), 54 de 214 tests de las suites existentes (test_dispositivos.py, test_mapeos.py, test_ingesta_cola.py y tests/tasks) fallan en regresión porque sus fixtures no crean una suscripción vigente. 46 son el 409 de modo consulta; el resto son errores en cascada y 3 o 4 casos no se analizaron por separado. Entre ellos están TestEliminarDispositivo::test_desactiva_el_dispositivo y TestReactivarDispositivo::test_reactiva_el_dispositivo, los tests originales de HU18. | E12: Agregar a tests/conftest.py un fixture común con suscripción vigente (como con_suscripcion_vigente en test_hu18_qa.py) y volver a ejecutar la suite. | F12: QA | G12: 28/10/2026 | H12: Abierta | I12: Mejora técnica | J12: Media | K12: Dev
A13: OBS-12 | B13: — | C13: HU-18 | D13: QA levantó en local Postgres y Redis con docker compose (puerto 5433), creó las bases pangea_test y pangea_e2e, instaló pyftpdlib y Playwright (backend/qa/playwright_hu18) y quitó la marca de cambio de contraseña solo en pangea_e2e. No se tocó el Postgres local existente (5432) ni producción. | E13: Descartar las bases y las cuentas del seed al terminar la ronda. | F13: QA | G13: 28/10/2026 | H13: Aceptada | I13: Entorno | J13: Baja | K13: QA | M13: 28/10/2026 | N13: Entorno local descartable; no afecta al producto.
A14: OBS-13 | B14: — | C14: HU-18 | D14: No se probó producción ni un datalogger real: el polling se verificó con un servidor FTP local (pyftpdlib) y con el sondeo de Celery real sobre la BD de test. El historial (PP-191) se verificó con la BD y GET /mediciones; no se midió cobertura de líneas. | E14: Repetir la prueba de polling en el servidor de pruebas cuando esté disponible y después de corregir DEF-04. | F14: QA | G14: 28/10/2026 | H14: Abierta | I14: Cobertura pendiente | J14: Media | K14: PO

Sheet Pendientes de entrega
A1: ID | B1: Subtarea | C1: Historia | D1: Qué falta | E1: Responsable | F1: Estado en Jira | G1: Estado real | H1: Fecha comprometida | I1: ¿Bloquea el cierre? | J1: Origen | K1: Comentario
A2: PEN-01 | B2: PP-125 | C2: HT-06 | D2: Receptor FTP/TCP en contenedor propio (el despliegue tiene api, worker, beat y redis; la ingesta usa sondeo desde Celery) | E2: Por definir (decision del PO) | F2: Listo | G2: Por hacer: no entregada | H2: Por definir | I2: Sí | J2: Subtarea PP-125 | K2: Ver OBS-01: el PO decide si el sondeo Celery reemplaza al receptor.
A3: PEN-02 | B3: PP-127 | C3: HT-06 | D3: Integracion de la app con Object Storage: cliente S3, variables del bucket y escritura de los .dat y las exportaciones. El bucket pangea-storage-prod ya existe | E3: Dev | F3: Listo | G3: Por hacer: no entregada | H3: Por definir | I3: Sí | J3: Subtarea PP-127 | K3: Sin boto3 ni variables de bucket en el despliegue activo.
A4: PEN-03 | B4: PP-129 | C4: HT-06 | D4: Tarea Celery beat de respaldo semanal de la BD hacia Object Storage, cifrada, con retencion de 12 meses | E4: Dev | F4: Listo | G4: Por hacer: no entregada | H4: Por definir | I4: Sí | J4: Subtarea PP-129 | K4: Hoy solo hay el respaldo automatico nativo de Lightsail y un snapshot manual (pangea-pre-b948aac-20261020).
A5: PEN-04 | B5: Sin subtarea | C5: HT-06 | D5: Tres entornos separados (desarrollo, staging y produccion) con variables de entorno propias | E5: Dev | F5: — | G5: Por hacer: no entregada | H5: Por definir | I5: Sí | J5: Procedimiento de la HU | K5: Solo existe produccion; el servidor de pruebas esta en curso.
A6: PEN-05 | B6: Sin subtarea | C6: HT-06 | D6: Documentar el umbral de migracion (5 clientes activos o dashboard > 3 s) y la restriccion de PostGIS en Lightsail | E6: Dev | F6: — | G6: Por hacer: no entregada | H6: Por definir | I6: No | J6: Procedimiento de la HU (v1.1) | K6: Los polígonos ya se guardan como GeoJSON en columna JSONB.

Sheet Historial de rondas
A1: Ronda | B1: Historia | C1: Fecha | D1: Commit probado | E1: Casos ejecutados | F1: Aprobados | G1: Fallidos | H1: Bloqueados | I1: Defectos nuevos | J1: Defectos cerrados | K1: Observaciones nuevas | L1: Evidencias | M1: Comentario
A2: 1 | B2: HT-06 | C2: 28/10/2026 | D2: bc5b89a (qa-elliot) | E2: 17 | F2: 11 | G2: 6 | H2: 12 | I2: 3 | J2: 0 | K2: 8 | L2: 31 | M2: Primera ronda: local (pytest, docker compose) y Lightsail en solo lectura. Sin prueba de redeploy ni de respaldo.
A3: 1 | B3: HU-18 | C3: 28/10/2026 | D3: 61fdd71 (qa-elliot) | E3: 29 | F3: 27 | G3: 2 | H3: 0 | I3: 1 | J3: 0 | K3: 5 | L3: 37 | M3: Primera ronda de HU-18: pytest con BD real de test, FTP local real (pyftpdlib) y Playwright con Edge. Sin producción. Quedan DEF-04 (PP-190) y la regresión RG-05 a RG-09 pendiente.
A41: 2 | B41: HU-18 | C41: 30/10/2026 | D41: 27ac90a (qa-elliot, incluye dccdb60) | E41: 29 | F41: 29 | G41: 0 | H41: 0 | I41: 0 | J41: 1 | K41: 0 | L41: 37 | M41: Segunda ronda de HU-18: DEF-04 corregido por Jareth (dccdb60) y verificado con pytest (BD de test), FTP local real y regresión. Playwright no se reejecutó (sin cambios de UI). Quedan OBS-09, OBS-10 y OBS-13 (PO) y OBS-11 (Dev).

Sheet Resumen
A1: Resumen de defectos
A3: Se calcula solo. No escribir en esta hoja.
A5: Indicador | B5: Cantidad | C5: % del total
A6: Defectos registrados | B6: =COUNTIF(Defectos!B2:B200,"?*")
A7: Severidad Crítica | B7: =COUNTIFS(Defectos!B2:B200,"?*",Defectos!F2:F200,"Crítica") | C7: =IF(B6=0,0,B7/B6)
A8: Severidad Alta | B8: =COUNTIFS(Defectos!B2:B200,"?*",Defectos!F2:F200,"Alta") | C8: =IF(B6=0,0,B8/B6)
A9: Severidad Media | B9: =COUNTIFS(Defectos!B2:B200,"?*",Defectos!F2:F200,"Media") | C9: =IF(B6=0,0,B9/B6)
A10: Severidad Baja | B10: =COUNTIFS(Defectos!B2:B200,"?*",Defectos!F2:F200,"Baja") | C10: =IF(B6=0,0,B10/B6)
A12: Por estado
A13: Indicador | B13: Cantidad | C13: % del total
A14: Defectos registrados | B14: =COUNTIF(Defectos!B2:B200,"?*")
A15: Pendiente (sin asignar a un estado del ciclo) | B15: =COUNTIFS(Defectos!B2:B200,"?*",Defectos!P2:P200,"Pendiente") | C15: =IF(B14=0,0,B15/B14)
A16: Nuevo | B16: =COUNTIFS(Defectos!B2:B200,"?*",Defectos!P2:P200,"Nuevo") | C16: =IF(B14=0,0,B16/B14)
A17: Asignado | B17: =COUNTIFS(Defectos!B2:B200,"?*",Defectos!P2:P200,"Asignado") | C17: =IF(B14=0,0,B17/B14)
A18: En corrección | B18: =COUNTIFS(Defectos!B2:B200,"?*",Defectos!P2:P200,"En corrección") | C18: =IF(B14=0,0,B18/B14)
A19: Corregido | B19: =COUNTIFS(Defectos!B2:B200,"?*",Defectos!P2:P200,"Corregido") | C19: =IF(B14=0,0,B19/B14)
A20: Cerrado | B20: =COUNTIFS(Defectos!B2:B200,"?*",Defectos!P2:P200,"Cerrado") | C20: =IF(B14=0,0,B20/B14)
A21: Reabierto | B21: =COUNTIFS(Defectos!B2:B200,"?*",Defectos!P2:P200,"Reabierto") | C21: =IF(B14=0,0,B21/B14)
A22: Rechazado | B22: =COUNTIFS(Defectos!B2:B200,"?*",Defectos!P2:P200,"Rechazado") | C22: =IF(B14=0,0,B22/B14)
A24: Por historia
A25: Indicador | B25: Cantidad | C25: % del total
A26: Defectos registrados | B26: =COUNTIF(Defectos!B2:B200,"?*")
A27: HT-06 | B27: =COUNTIFS(Defectos!B2:B200,"?*",Defectos!C2:C200,LEFT($A27,FIND(" ",$A27&" ")-1)) | C27: =IF(B26=0,0,B27/B26)
A28: HU-18 | B28: =COUNTIFS(Defectos!B2:B200,"?*",Defectos!C2:C200,LEFT($A28,FIND(" ",$A28&" ")-1)) | C28: =IF(B26=0,0,B28/B26)
A30: Abiertos que bloquean el cierre
A31: Indicador | B31: Cantidad | C31: % del total
A32: Críticos o Altos sin cerrar | B32: =SUMPRODUCT((Defectos!B2:B200<>"")*((Defectos!F2:F200="Crítica")+(Defectos!F2:F200="Alta"))*(Defectos!P2:P200<>"Cerrado")*(Defectos!P2:P200<>"Rechazado")) | C32: =IF(B6=0,0,B32/B6)
A34: Un defecto cuenta como registrado cuando tiene ID y Título.
A36: Criterio de cierre: ningún defecto Crítico o Alto abierto.
A38: Observaciones por estado
A39: Indicador | B39: Cantidad | C39: % del total
A40: Observaciones registradas | B40: =COUNTIF(Observaciones!A2:A200,"OBS-*")
A41: Abiertas | B41: =COUNTIFS(Observaciones!A2:A200,"OBS-*",Observaciones!H2:H200,"Abierta") | C41: =IF(B40=0,0,B41/B40)
A42: Aceptadas | B42: =COUNTIFS(Observaciones!A2:A200,"OBS-*",Observaciones!H2:H200,"Aceptada") | C42: =IF(B40=0,0,B42/B40)
A43: Descartadas | B43: =COUNTIFS(Observaciones!A2:A200,"OBS-*",Observaciones!H2:H200,"Descartada") | C43: =IF(B40=0,0,B43/B40)
A44: Trasladadas a Pendientes de entrega | B44: =COUNTIFS(Observaciones!A2:A200,"OBS-*",Observaciones!H2:H200,"Trasladada") | C44: =IF(B40=0,0,B44/B40)
A46: Observaciones abiertas por responsable
A47: Indicador | B47: Cantidad | C47: % del total
A48: Abiertas | B48: =COUNTIFS(Observaciones!A2:A200,"OBS-*",Observaciones!H2:H200,"Abierta")
A49: Esperan decisión del PO | B49: =COUNTIFS(Observaciones!H2:H200,"Abierta",Observaciones!K2:K200,"PO") | C49: =IF(B48=0,0,B49/B48)
...
